Workbook

Sheet SUMMARY
A1: HOT COST — DEPARTMENT SUMMARY
A2: (over) / under against the budgeted day. Negative is over. Updates as day sheets are filled in.
A4: DEPARTMENT | B4: preshoot | C4: 16 Oct | D4: 17 Oct | E4: 18 Oct | F4: 19 Oct | G4: 20 Oct | H4: 23 Oct | I4: 24 Oct | J4: 25 Oct | K4: 26 Oct | L4: 27 Oct | M4: 30 Oct | N4: 31 Oct | O4: 01 Nov | P4: 02 Nov | Q4: 03 Nov | R4: 06 Nov | S4: 07 Nov | T4: 08 Nov | U4: 09 Nov | V4: 10 Nov | W4: 13 Nov | X4: 14 Nov | Y4: 15 Nov | Z4: 16 Nov | AA4: 17 Nov | AB4: TOTAL
A5: CAST | B5: ='101317 PRESHOOT'!R28+'101317 PRESHOOT'!R29 | C5: ='101617'!R28+'101617'!R29 | D5: ='101717'!R28+'101717'!R29 | E5: ='101817'!R28+'101817'!R29 | F5: ='101917'!R28+'101917'!R29 | G5: ='102017'!R28+'102017'!R29 | H5: ='102317'!R28+'102317'!R29 | I5: ='102417'!R28+'102417'!R29 | J5: ='102517'!R28+'102517'!R29 | K5: ='102617'!R28+'102617'!R29 | L5: ='102717'!R28+'102717'!R29 | M5: ='103017'!R28+'103017'!R29 | N5: ='103117'!R28+'103117'!R29 | O5: ='110117'!R28+'110117'!R29 | P5: ='110217'!R28+'110217'!R29 | Q5: ='110317'!R28+'110317'!R29 | R5: ='110617'!R28+'110617'!R29 | S5: ='110717'!R28+'110717'!R29 | T5: ='110817'!R28+'110817'!R29 | U5: ='110917'!R28+'110917'!R29 | V5: ='111017'!R28+'111017'!R29 | W5: ='111317'!R28+'111317'!R29 | X5: ='111417'!R28+'111417'!R29 | Y5: ='111517'!R28+'111517'!R29 | Z5: ='111617'!R28+'111617'!R29 | AA5: ='111717'!R28+'111717'!R29 | AB5: =SUM(B5:AA5)
A6: PRODUCTION STAFF | B6: ='101317 PRESHOOT'!R51+'101317 PRESHOOT'!R52 | C6: ='101617'!R51+'101617'!R52 | D6: ='101717'!R51+'101717'!R52 | E6: ='101817'!R51+'101817'!R52 | F6: ='101917'!R51+'101917'!R52 | G6: ='102017'!R51+'102017'!R52 | H6: ='102317'!R51+'102317'!R52 | I6: ='102417'!R51+'102417'!R52 | J6: ='102517'!R51+'102517'!R52 | K6: ='102617'!R51+'102617'!R52 | L6: ='102717'!R51+'102717'!R52 | M6: ='103017'!R51+'103017'!R52 | N6: ='103117'!R51+'103117'!R52 | O6: ='110117'!R51+'110117'!R52 | P6: ='110217'!R51+'110217'!R52 | Q6: ='110317'!R51+'110317'!R52 | R6: ='110617'!R51+'110617'!R52 | S6: ='110717'!R51+'110717'!R52 | T6: ='110817'!R51+'110817'!R52 | U6: ='110917'!R51+'110917'!R52 | V6: ='111017'!R51+'111017'!R52 | W6: ='111317'!R51+'111317'!R52 | X6: ='111417'!R51+'111417'!R52 | Y6: ='111517'!R51+'111517'!R52 | Z6: ='111617'!R51+'111617'!R52 | AA6: ='111717'!R51+'111717'!R52 | AB6: =SUM(B6:AA6)
A7: SET CONSTRUCTION | B7: ='101317 PRESHOOT'!R58+'101317 PRESHOOT'!R59 | C7: ='101617'!R58+'101617'!R59 | D7: ='101717'!R58+'101717'!R59 | E7: ='101817'!R58+'101817'!R59 | F7: ='101917'!R58+'101917'!R59 | G7: ='102017'!R58+'102017'!R59 | H7: ='102317'!R58+'102317'!R59 | I7: ='102417'!R58+'102417'!R59 | J7: ='102517'!R58+'102517'!R59 | K7: ='102617'!R58+'102617'!R59 | L7: ='102717'!R58+'102717'!R59 | M7: ='103017'!R58+'103017'!R59 | N7: ='103117'!R58+'103117'!R59 | O7: ='110117'!R58+'110117'!R59 | P7: ='110217'!R58+'110217'!R59 | Q7: ='110317'!R58+'110317'!R59 | R7: ='110617'!R58+'110617'!R59 | S7: ='110717'!R58+'110717'!R59 | T7: ='110817'!R58+'110817'!R59 | U7: ='110917'!R58+'110917'!R59 | V7: ='111017'!R58+'111017'!R59 | W7: ='111317'!R58+'111317'!R59 | X7: ='111417'!R58+'111417'!R59 | Y7: ='111517'!R58+'111517'!R59 | Z7: ='111617'!R58+'111617'!R59 | AA7: ='111717'!R58+'111717'!R59 | AB7: =SUM(B7:AA7)
A8: SET OPERATIONS | B8: ='101317 PRESHOOT'!R77+'101317 PRESHOOT'!R78 | C8: ='101617'!R77+'101617'!R78 | D8: ='101717'!R77+'101717'!R78 | E8: ='101817'!R77+'101817'!R78 | F8: ='101917'!R77+'101917'!R78 | G8: ='102017'!R77+'102017'!R78 | H8: ='102317'!R77+'102317'!R78 | I8: ='102417'!R77+'102417'!R78 | J8: ='102517'!R77+'102517'!R78 | K8: ='102617'!R77+'102617'!R78 | L8: ='102717'!R77+'102717'!R78 | M8: ='103017'!R77+'103017'!R78 | N8: ='103117'!R77+'103117'!R78 | O8: ='110117'!R77+'110117'!R78 | P8: ='110217'!R77+'110217'!R78 | Q8: ='110317'!R77+'110317'!R78 | R8: ='110617'!R77+'110617'!R78 | S8: ='110717'!R77+'110717'!R78 | T8: ='110817'!R77+'110817'!R78 | U8: ='110917'!R77+'110917'!R78 | V8: ='111017'!R77+'111017'!R78 | W8: ='111317'!R77+'111317'!R78 | X8: ='111417'!R77+'111417'!R78 | Y8: ='111517'!R77+'111517'!R78 | Z8: ='111617'!R77+'111617'!R78 | AA8: ='111717'!R77+'111717'!R78 | AB8: =SUM(B8:AA8)
A9: SPECIAL EFFECTS | B9: ='101317 PRESHOOT'!R85+'101317 PRESHOOT'!R86 | C9: ='101617'!R85+'101617'!R86 | D9: ='101717'!R85+'101717'!R86 | E9: ='101817'!R85+'101817'!R86 | F9: ='101917'!R85+'101917'!R86 | G9: ='102017'!R85+'102017'!R86 | H9: ='102317'!R85+'102317'!R86 | I9: ='102417'!R85+'102417'!R86 | J9: ='102517'!R85+'102517'!R86 | K9: ='102617'!R85+'102617'!R86 | L9: ='102717'!R85+'102717'!R86 | M9: ='103017'!R85+'103017'!R86 | N9: ='103117'!R85+'103117'!R86 | O9: ='110117'!R85+'110117'!R86 | P9: ='110217'!R85+'110217'!R86 | Q9: ='110317'!R85+'110317'!R86 | R9: ='110617'!R85+'110617'!R86 | S9: ='110717'!R85+'110717'!R86 | T9: ='110817'!R85+'110817'!R86 | U9: ='110917'!R85+'110917'!R86 | V9: ='111017'!R85+'111017'!R86 | W9: ='111317'!R85+'111317'!R86 | X9: ='111417'!R85+'111417'!R86 | Y9: ='111517'!R85+'111517'!R86 | Z9: ='111617'!R85+'111617'!R86 | AA9: ='111717'!R85+'111717'!R86 | AB9: =SUM(B9:AA9)
A10: SET DRESSING | B10: ='101317 PRESHOOT'!R96+'101317 PRESHOOT'!R97 | C10: ='101617'!R96+'101617'!R97 | D10: ='101717'!R96+'101717'!R97 | E10: ='101817'!R96+'101817'!R97 | F10: ='101917'!R96+'101917'!R97 | G10: ='102017'!R96+'102017'!R97 | H10: ='102317'!R96+'102317'!R97 | I10: ='102417'!R96+'102417'!R97 | J10: ='102517'!R96+'102517'!R97 | K10: ='102617'!R96+'102617'!R97 | L10: ='102717'!R96+'102717'!R97 | M10: ='103017'!R96+'103017'!R97 | N10: ='103117'!R96+'103117'!R97 | O10: ='110117'!R96+'110117'!R97 | P10: ='110217'!R96+'110217'!R97 | Q10: ='110317'!R96+'110317'!R97 | R10: ='110617'!R96+'110617'!R97 | S10: ='110717'!R96+'110717'!R97 | T10: ='110817'!R96+'110817'!R97 | U10: ='110917'!R96+'110917'!R97 | V10: ='111017'!R96+'111017'!R97 | W10: ='111317'!R96+'111317'!R97 | X10: ='111417'!R96+'111417'!R97 | Y10: ='111517'!R96+'111517'!R97 | Z10: ='111617'!R96+'111617'!R97 | AA10: ='111717'!R96+'111717'!R97 | AB10: =SUM(B10:AA10)
A11: PROPERTY | B11: ='101317 PRESHOOT'!R102+'101317 PRESHOOT'!R103 | C11: ='101617'!R102+'101617'!R103 | D11: ='101717'!R102+'101717'!R103 | E11: ='101817'!R102+'101817'!R103 | F11: ='101917'!R102+'101917'!R103 | G11: ='102017'!R102+'102017'!R103 | H11: ='102317'!R102+'102317'!R103 | I11: ='102417'!R102+'102417'!R103 | J11: ='102517'!R102+'102517'!R103 | K11: ='102617'!R102+'102617'!R103 | L11: ='102717'!R102+'102717'!R103 | M11: ='103017'!R102+'103017'!R103 | N11: ='103117'!R102+'103117'!R103 | O11: ='110117'!R102+'110117'!R103 | P11: ='110217'!R102+'110217'!R103 | Q11: ='110317'!R102+'110317'!R103 | R11: ='110617'!R102+'110617'!R103 | S11: ='110717'!R102+'110717'!R103 | T11: ='110817'!R102+'110817'!R103 | U11: ='110917'!R102+'110917'!R103 | V11: ='111017'!R102+'111017'!R103 | W11: ='111317'!R102+'111317'!R103 | X11: ='111417'!R102+'111417'!R103 | Y11: ='111517'!R102+'111517'!R103 | Z11: ='111617'!R102+'111617'!R103 | AA11: ='111717'!R102+'111717'!R103 | AB11: =SUM(B11:AA11)
A12: WARDROBE | B12: ='101317 PRESHOOT'!R110+'101317 PRESHOOT'!R111 | C12: ='101617'!R110+'101617'!R111 | D12: ='101717'!R110+'101717'!R111 | E12: ='101817'!R110+'101817'!R111 | F12: ='101917'!R110+'101917'!R111 | G12: ='102017'!R110+'102017'!R111 | H12: ='102317'!R110+'102317'!R111 | I12: ='102417'!R110+'102417'!R111 | J12: ='102517'!R110+'102517'!R111 | K12: ='102617'!R110+'102617'!R111 | L12: ='102717'!R110+'102717'!R111 | M12: ='103017'!R110+'103017'!R111 | N12: ='103117'!R110+'103117'!R111 | O12: ='110117'!R110+'110117'!R111 | P12: ='110217'!R110+'110217'!R111 | Q12: ='110317'!R110+'110317'!R111 | R12: ='110617'!R110+'110617'!R111 | S12: ='110717'!R110+'110717'!R111 | T12: ='110817'!R110+'110817'!R111 | U12: ='110917'!R110+'110917'!R111 | V12: ='111017'!R110+'111017'!R111 | W12: ='111317'!R110+'111317'!R111 | X12: ='111417'!R110+'111417'!R111 | Y12: ='111517'!R110+'111517'!R111 | Z12: ='111617'!R110+'111617'!R111 | AA12: ='111717'!R110+'111717'!R111 | AB12: =SUM(B12:AA12)
A13: MAKE-UP&HAIR | B13: ='101317 PRESHOOT'!R122+'101317 PRESHOOT'!R123 | C13: ='101617'!R122+'101617'!R123 | D13: ='101717'!R122+'101717'!R123 | E13: ='101817'!R122+'101817'!R123 | F13: ='101917'!R122+'101917'!R123 | G13: ='102017'!R122+'102017'!R123 | H13: ='102317'!R122+'102317'!R123 | I13: ='102417'!R122+'102417'!R123 | J13: ='102517'!R122+'102517'!R123 | K13: ='102617'!R122+'102617'!R123 | L13: ='102717'!R122+'102717'!R123 | M13: ='103017'!R122+'103017'!R123 | N13: ='103117'!R122+'103117'!R123 | O13: ='110117'!R122+'110117'!R123 | P13: ='110217'!R122+'110217'!R123 | Q13: ='110317'!R122+'110317'!R123 | R13: ='110617'!R122+'110617'!R123 | S13: ='110717'!R122+'110717'!R123 | T13: ='110817'!R122+'110817'!R123 | U13: ='110917'!R122+'110917'!R123 | V13: ='111017'!R122+'111017'!R123 | W13: ='111317'!R122+'111317'!R123 | X13: ='111417'!R122+'111417'!R123 | Y13: ='111517'!R122+'111517'!R123 | Z13: ='111617'!R122+'111617'!R123 | AA13: ='111717'!R122+'111717'!R123 | AB13: =SUM(B13:AA13)
A14: SET LIGHTING | B14: ='101317 PRESHOOT'!R133+'101317 PRESHOOT'!R134 | C14: ='101617'!R133+'101617'!R134 | D14: ='101717'!R133+'101717'!R134 | E14: ='101817'!R133+'101817'!R134 | F14: ='101917'!R133+'101917'!R134 | G14: ='102017'!R133+'102017'!R134 | H14: ='102317'!R133+'102317'!R134 | I14: ='102417'!R133+'102417'!R134 | J14: ='102517'!R133+'102517'!R134 | K14: ='102617'!R133+'102617'!R134 | L14: ='102717'!R133+'102717'!R134 | M14: ='103017'!R133+'103017'!R134 | N14: ='103117'!R133+'103117'!R134 | O14: ='110117'!R133+'110117'!R134 | P14: ='110217'!R133+'110217'!R134 | Q14: ='110317'!R133+'110317'!R134 | R14: ='110617'!R133+'110617'!R134 | S14: ='110717'!R133+'110717'!R134 | T14: ='110817'!R133+'110817'!R134 | U14: ='110917'!R133+'110917'!R134 | V14: ='111017'!R133+'111017'!R134 | W14: ='111317'!R133+'111317'!R134 | X14: ='111417'!R133+'111417'!R134 | Y14: ='111517'!R133+'111517'!R134 | Z14: ='111617'!R133+'111617'!R134 | AA14: ='111717'!R133+'111717'!R134 | AB14: =SUM(B14:AA14)
A15: CAMERA | B15: ='101317 PRESHOOT'!R146+'101317 PRESHOOT'!R147 | C15: ='101617'!R146+'101617'!R147 | D15: ='101717'!R146+'101717'!R147 | E15: ='101817'!R146+'101817'!R147 | F15: ='101917'!R146+'101917'!R147 | G15: ='102017'!R146+'102017'!R147 | H15: ='102317'!R146+'102317'!R147 | I15: ='102417'!R146+'102417'!R147 | J15: ='102517'!R146+'102517'!R147 | K15: ='102617'!R146+'102617'!R147 | L15: ='102717'!R146+'102717'!R147 | M15: ='103017'!R146+'103017'!R147 | N15: ='103117'!R146+'103117'!R147 | O15: ='110117'!R146+'110117'!R147 | P15: ='110217'!R146+'110217'!R147 | Q15: ='110317'!R146+'110317'!R147 | R15: ='110617'!R146+'110617'!R147 | S15: ='110717'!R146+'110717'!R147 | T15: ='110817'!R146+'110817'!R147 | U15: ='110917'!R146+'110917'!R147 | V15: ='111017'!R146+'111017'!R147 | W15: ='111317'!R146+'111317'!R147 | X15: ='111417'!R146+'111417'!R147 | Y15: ='111517'!R146+'111517'!R147 | Z15: ='111617'!R146+'111617'!R147 | AA15: ='111717'!R146+'111717'!R147 | AB15: =SUM(B15:AA15)
A16: PRODUCTION SOUND | B16: ='101317 PRESHOOT'!R154+'101317 PRESHOOT'!R155 | C16: ='101617'!R154+'101617'!R155 | D16: ='101717'!R154+'101717'!R155 | E16: ='101817'!R154+'101817'!R155 | F16: ='101917'!R154+'101917'!R155 | G16: ='102017'!R154+'102017'!R155 | H16: ='102317'!R154+'102317'!R155 | I16: ='102417'!R154+'102417'!R155 | J16: ='102517'!R154+'102517'!R155 | K16: ='102617'!R154+'102617'!R155 | L16: ='102717'!R154+'102717'!R155 | M16: ='103017'!R154+'103017'!R155 | N16: ='103117'!R154+'103117'!R155 | O16: ='110117'!R154+'110117'!R155 | P16: ='110217'!R154+'110217'!R155 | Q16: ='110317'!R154+'110317'!R155 | R16: ='110617'!R154+'110617'!R155 | S16: ='110717'!R154+'110717'!R155 | T16: ='110817'!R154+'110817'!R155 | U16: ='110917'!R154+'110917'!R155 | V16: ='111017'!R154+'111017'!R155 | W16: ='111317'!R154+'111317'!R155 | X16: ='111417'!R154+'111417'!R155 | Y16: ='111517'!R154+'111517'!R155 | Z16: ='111617'!R154+'111617'!R155 | AA16: ='111717'!R154+'111717'!R155 | AB16: =SUM(B16:AA16)
A17: TRANSPORTATION | B17: ='101317 PRESHOOT'!R172+'101317 PRESHOOT'!R173 | C17: ='101617'!R172+'101617'!R173 | D17: ='101717'!R172+'101717'!R173 | E17: ='101817'!R172+'101817'!R173 | F17: ='101917'!R172+'101917'!R173 | G17: ='102017'!R172+'102017'!R173 | H17: ='102317'!R172+'102317'!R173 | I17: ='102417'!R172+'102417'!R173 | J17: ='102517'!R172+'102517'!R173 | K17: ='102617'!R172+'102617'!R173 | L17: ='102717'!R172+'102717'!R173 | M17: ='103017'!R172+'103017'!R173 | N17: ='103117'!R172+'103117'!R173 | O17: ='110117'!R172+'110117'!R173 | P17: ='110217'!R172+'110217'!R173 | Q17: ='110317'!R172+'110317'!R173 | R17: ='110617'!R172+'110617'!R173 | S17: ='110717'!R172+'110717'!R173 | T17: ='110817'!R172+'110817'!R173 | U17: ='110917'!R172+'110917'!R173 | V17: ='111017'!R172+'111017'!R173 | W17: ='111317'!R172+'111317'!R173 | X17: ='111417'!R172+'111417'!R173 | Y17: ='111517'!R172+'111517'!R173 | Z17: ='111617'!R172+'111617'!R173 | AA17: ='111717'!R172+'111717'!R173 | AB17: =SUM(B17:AA17)
A18: LOCATIONS | B18: ='101317 PRESHOOT'!R180+'101317 PRESHOOT'!R181 | C18: ='101617'!R180+'101617'!R181 | D18: ='101717'!R180+'101717'!R181 | E18: ='101817'!R180+'101817'!R181 | F18: ='101917'!R180+'101917'!R181 | G18: ='102017'!R180+'102017'!R181 | H18: ='102317'!R180+'102317'!R181 | I18: ='102417'!R180+'102417'!R181 | J18: ='102517'!R180+'102517'!R181 | K18: ='102617'!R180+'102617'!R181 | L18: ='102717'!R180+'102717'!R181 | M18: ='103017'!R180+'103017'!R181 | N18: ='103117'!R180+'103117'!R181 | O18: ='110117'!R180+'110117'!R181 | P18: ='110217'!R180+'110217'!R181 | Q18: ='110317'!R180+'110317'!R181 | R18: ='110617'!R180+'110617'!R181 | S18: ='110717'!R180+'110717'!R181 | T18: ='110817'!R180+'110817'!R181 | U18: ='110917'!R180+'110917'!R181 | V18: ='111017'!R180+'111017'!R181 | W18: ='111317'!R180+'111317'!R181 | X18: ='111417'!R180+'111417'!R181 | Y18: ='111517'!R180+'111517'!R181 | Z18: ='111617'!R180+'111617'!R181 | AA18: ='111717'!R180+'111717'!R181 | AB18: =SUM(B18:AA18)
A19: TOTAL | B19: =SUM(B5:B18) | C19: =SUM(C5:C18) | D19: =SUM(D5:D18) | E19: =SUM(E5:E18) | F19: =SUM(F5:F18) | G19: =SUM(G5:G18) | H19: =SUM(H5:H18) | I19: =SUM(I5:I18) | ... AB19: =SUM(AB5:AB18)

Sheet WEEKLY
A1: HOT COST — WEEKLY ROLL-UP
A2: actual, budget and variance by department by shoot week
B3: Preshoot | E3: Week 1 | H3: Week 2 | K3: Week 3 | N3: Week 4 | Q3: Week 5
A4: DEPARTMENT | B4: ACTUAL | C4: BUDGET | D4: (OVER)/UNDER | E4: ACTUAL | F4: BUDGET | G4: (OVER)/UNDER | H4: ACTUAL | I4: BUDGET | J4: (OVER)/UNDER | K4: ACTUAL | L4: BUDGET | M4: (OVER)/UNDER | N4: ACTUAL | O4: BUDGET | P4: (OVER)/UNDER | Q4: ACTUAL | R4: BUDGET | S4: (OVER)/UNDER
A5: CAST | B5: ='101317 PRESHOOT'!P28+'101317 PRESHOOT'!P29 | C5: ='101317 PRESHOOT'!Q28+'101317 PRESHOOT'!Q29 | D5: ='101317 PRESHOOT'!R28+'101317 PRESHOOT'!R29 | E5: ='101617'!P28+'101617'!P29+'101717'!P28+'101717'!P29+'101817'!P28+'101817'!P29+'101917'!P28+'101917'!P29+'102017'!P28+'102017'!P29 | F5: ='101617'!Q28+'101617'!Q29+'101717'!Q28+'101717'!Q29+'101817'!Q28+'101817'!Q29+'101917'!Q28+'101917'!Q29+'102017'!Q28+'102017'!Q29 | G5: ='101617'!R28+'101617'!R29+'101717'!R28+'101717'!R29+'101817'!R28+'101817'!R29+'101917'!R28+'101917'!R29+'102017'!R28+'102017'!R29 | H5: ='102317'!P28+'102317'!P29+'102417'!P28+'102417'!P29+'102517'!P28+'102517'!P29+'102617'!P28+'102617'!P29+'102717'!P28+'102717'!P29 | I5: ='102317'!Q28+'102317'!Q29+'102417'!Q28+'102417'!Q29+'102517'!Q28+'102517'!Q29+'102617'!Q28+'102617'!Q29+'102717'!Q28+'102717'!Q29 | J5: ='102317'!R28+'102317'!R29+'102417'!R28+'102417'!R29+'102517'!R28+'102517'!R29+'102617'!R28+'102617'!R29+'102717'!R28+'102717'!R29 | K5: ='103017'!P28+'103017'!P29+'103117'!P28+'103117'!P29+'110117'!P28+'110117'!P29+'110217'!P28+'110217'!P29+'110317'!P28+'110317'!P29 | L5: ='103017'!Q28+'103017'!Q29+'103117'!Q28+'103117'!Q29+'110117'!Q28+'110117'!Q29+'110217'!Q28+'110217'!Q29+'110317'!Q28+'110317'!Q29 | M5: ='103017'!R28+'103017'!R29+'103117'!R28+'103117'!R29+'110117'!R28+'110117'!R29+'110217'!R28+'110217'!R29+'110317'!R28+'110317'!R29 | N5: ='110617'!P28+'110617'!P29+'110717'!P28+'110717'!P29+'110817'!P28+'110817'!P29+'110917'!P28+'110917'!P29+'111017'!P28+'111017'!P29 | O5: ='110617'!Q28+'110617'!Q29+'110717'!Q28+'110717'!Q29+'110817'!Q28+'110817'!Q29+'110917'!Q28+'110917'!Q29+'111017'!Q28+'111017'!Q29 | P5: ='110617'!R28+'110617'!R29+'110717'!R28+'110717'!R29+'110817'!R28+'110817'!R29+'110917'!R28+'110917'!R29+'111017'!R28+'111017'!R29 | Q5: ='111317'!P28+'111317'!P29+'111417'!P28+'111417'!P29+'111517'!P28+'111517'!P29+'111617'!P28+'111617'!P29+'111717'!P28+'111717'!P29 | R5: ='111317'!Q28+'111317'!Q29+'111417'!Q28+'111417'!Q29+'111517'!Q28+'111517'!Q29+'111617'!Q28+'111617'!Q29+'111717'!Q28+'111717'!Q29 | S5: ='111317'!R28+'111317'!R29+'111417'!R28+'111417'!R29+'111517'!R28+'111517'!R29+'111617'!R28+'111617'!R29+'111717'!R28+'111717'!R29
A6: PRODUCTION STAFF | B6: ='101317 PRESHOOT'!P51+'101317 PRESHOOT'!P52 | C6: ='101317 PRESHOOT'!Q51+'101317 PRESHOOT'!Q52 | D6: ='101317 PRESHOOT'!R51+'101317 PRESHOOT'!R52 | E6: ='101617'!P51+'101617'!P52+'101717'!P51+'101717'!P52+'101817'!P51+'101817'!P52+'101917'!P51+'101917'!P52+'102017'!P51+'102017'!P52 | F6: ='101617'!Q51+'101617'!Q52+'101717'!Q51+'101717'!Q52+'101817'!Q51+'101817'!Q52+'101917'!Q51+'101917'!Q52+'102017'!Q51+'102017'!Q52 | G6: ='101617'!R51+'101617'!R52+'101717'!R51+'101717'!R52+'101817'!R51+'101817'!R52+'101917'!R51+'101917'!R52+'102017'!R51+'102017'!R52 | H6: ='102317'!P51+'102317'!P52+'102417'!P51+'102417'!P52+'102517'!P51+'102517'!P52+'102617'!P51+'102617'!P52+'102717'!P51+'102717'!P52 | I6: ='102317'!Q51+'102317'!Q52+'102417'!Q51+'102417'!Q52+'102517'!Q51+'102517'!Q52+'102617'!Q51+'102617'!Q52+'102717'!Q51+'102717'!Q52 | J6: ='102317'!R51+'102317'!R52+'102417'!R51+'102417'!R52+'102517'!R51+'102517'!R52+'102617'!R51+'102617'!R52+'102717'!R51+'102717'!R52 | K6: ='103017'!P51+'103017'!P52+'103117'!P51+'103117'!P52+'110117'!P51+'110117'!P52+'110217'!P51+'110217'!P52+'110317'!P51+'110317'!P52 | L6: ='103017'!Q51+'103017'!Q52+'103117'!Q51+'103117'!Q52+'110117'!Q51+'110117'!Q52+'110217'!Q51+'110217'!Q52+'110317'!Q51+'110317'!Q52 | M6: ='103017'!R51+'103017'!R52+'103117'!R51+'103117'!R52+'110117'!R51+'110117'!R52+'110217'!R51+'110217'!R52+'110317'!R51+'110317'!R52 | N6: ='110617'!P51+'110617'!P52+'110717'!P51+'110717'!P52+'110817'!P51+'110817'!P52+'110917'!P51+'110917'!P52+'111017'!P51+'111017'!P52 | O6: ='110617'!Q51+'110617'!Q52+'110717'!Q51+'110717'!Q52+'110817'!Q51+'110817'!Q52+'110917'!Q51+'110917'!Q52+'111017'!Q51+'111017'!Q52 | P6: ='110617'!R51+'110617'!R52+'110717'!R51+'110717'!R52+'110817'!R51+'110817'!R52+'110917'!R51+'110917'!R52+'111017'!R51+'111017'!R52 | Q6: ='111317'!P51+'111317'!P52+'111417'!P51+'111417'!P52+'111517'!P51+'111517'!P52+'111617'!P51+'111617'!P52+'111717'!P51+'111717'!P52 | R6: ='111317'!Q51+'111317'!Q52+'111417'!Q51+'111417'!Q52+'111517'!Q51+'111517'!Q52+'111617'!Q51+'111617'!Q52+'111717'!Q51+'111717'!Q52 | S6: ='111317'!R51+'111317'!R52+'111417'!R51+'111417'!R52+'111517'!R51+'111517'!R52+'111617'!R51+'111617'!R52+'111717'!R51+'111717'!R52
A7: SET CONSTRUCTION | B7: ='101317 PRESHOOT'!P58+'101317 PRESHOOT'!P59 | C7: ='101317 PRESHOOT'!Q58+'101317 PRESHOOT'!Q59 | D7: ='101317 PRESHOOT'!R58+'101317 PRESHOOT'!R59 | E7: ='101617'!P58+'101617'!P59+'101717'!P58+'101717'!P59+'101817'!P58+'101817'!P59+'101917'!P58+'101917'!P59+'102017'!P58+'102017'!P59 | F7: ='101617'!Q58+'101617'!Q59+'101717'!Q58+'101717'!Q59+'101817'!Q58+'101817'!Q59+'101917'!Q58+'101917'!Q59+'102017'!Q58+'102017'!Q59 | G7: ='101617'!R58+'101617'!R59+'101717'!R58+'101717'!R59+'101817'!R58+'101817'!R59+'101917'!R58+'101917'!R59+'102017'!R58+'102017'!R59 | H7: ='102317'!P58+'102317'!P59+'102417'!P58+'102417'!P59+'102517'!P58+'102517'!P59+'102617'!P58+'102617'!P59+'102717'!P58+'102717'!P59 | I7: ='102317'!Q58+'102317'!Q59+'102417'!Q58+'102417'!Q59+'102517'!Q58+'102517'!Q59+'102617'!Q58+'102617'!Q59+'102717'!Q58+'102717'!Q59 | J7: ='102317'!R58+'102317'!R59+'102417'!R58+'102417'!R59+'102517'!R58+'102517'!R59+'102617'!R58+'102617'!R59+'102717'!R58+'102717'!R59 | K7: ='103017'!P58+'103017'!P59+'103117'!P58+'103117'!P59+'110117'!P58+'110117'!P59+'110217'!P58+'110217'!P59+'110317'!P58+'110317'!P59 | L7: ='103017'!Q58+'103017'!Q59+'103117'!Q58+'103117'!Q59+'110117'!Q58+'110117'!Q59+'110217'!Q58+'110217'!Q59+'110317'!Q58+'110317'!Q59 | M7: ='103017'!R58+'103017'!R59+'103117'!R58+'103117'!R59+'110117'!R58+'110117'!R59+'110217'!R58+'110217'!R59+'110317'!R58+'110317'!R59 | N7: ='110617'!P58+'110617'!P59+'110717'!P58+'110717'!P59+'110817'!P58+'110817'!P59+'110917'!P58+'110917'!P59+'111017'!P58+'111017'!P59 | O7: ='110617'!Q58+'110617'!Q59+'110717'!Q58+'110717'!Q59+'110817'!Q58+'110817'!Q59+'110917'!Q58+'110917'!Q59+'111017'!Q58+'111017'!Q59 | P7: ='110617'!R58+'110617'!R59+'110717'!R58+'110717'!R59+'110817'!R58+'110817'!R59+'110917'!R58+'110917'!R59+'111017'!R58+'111017'!R59 | Q7: ='111317'!P58+'111317'!P59+'111417'!P58+'111417'!P59+'111517'!P58+'111517'!P59+'111617'!P58+'111617'!P59+'111717'!P58+'111717'!P59 | R7: ='111317'!Q58+'111317'!Q59+'111417'!Q58+'111417'!Q59+'111517'!Q58+'111517'!Q59+'111617'!Q58+'111617'!Q59+'111717'!Q58+'111717'!Q59 | S7: ='111317'!R58+'111317'!R59+'111417'!R58+'111417'!R59+'111517'!R58+'111517'!R59+'111617'!R58+'111617'!R59+'111717'!R58+'111717'!R59
A8: SET OPERATIONS | B8: ='101317 PRESHOOT'!P77+'101317 PRESHOOT'!P78 | C8: ='101317 PRESHOOT'!Q77+'101317 PRESHOOT'!Q78 | D8: ='101317 PRESHOOT'!R77+'101317 PRESHOOT'!R78 | E8: ='101617'!P77+'101617'!P78+'101717'!P77+'101717'!P78+'101817'!P77+'101817'!P78+'101917'!P77+'101917'!P78+'102017'!P77+'102017'!P78 | F8: ='101617'!Q77+'101617'!Q78+'101717'!Q77+'101717'!Q78+'101817'!Q77+'101817'!Q78+'101917'!Q77+'101917'!Q78+'102017'!Q77+'102017'!Q78 | G8: ='101617'!R77+'101617'!R78+'101717'!R77+'101717'!R78+'101817'!R77+'101817'!R78+'101917'!R77+'101917'!R78+'102017'!R77+'102017'!R78 | H8: ='102317'!P77+'102317'!P78+'102417'!P77+'102417'!P78+'102517'!P77+'102517'!P78+'102617'!P77+'102617'!P78+'102717'!P77+'102717'!P78 | I8: ='102317'!Q77+'102317'!Q78+'102417'!Q77+'102417'!Q78+'102517'!Q77+'102517'!Q78+'102617'!Q77+'102617'!Q78+'102717'!Q77+'102717'!Q78 | J8: ='102317'!R77+'102317'!R78+'102417'!R77+'102417'!R78+'102517'!R77+'102517'!R78+'102617'!R77+'102617'!R78+'102717'!R77+'102717'!R78 | K8: ='103017'!P77+'103017'!P78+'103117'!P77+'103117'!P78+'110117'!P77+'110117'!P78+'110217'!P77+'110217'!P78+'110317'!P77+'110317'!P78 | L8: ='103017'!Q77+'103017'!Q78+'103117'!Q77+'103117'!Q78+'110117'!Q77+'110117'!Q78+'110217'!Q77+'110217'!Q78+'110317'!Q77+'110317'!Q78 | M8: ='103017'!R77+'103017'!R78+'103117'!R77+'103117'!R78+'110117'!R77+'110117'!R78+'110217'!R77+'110217'!R78+'110317'!R77+'110317'!R78 | N8: ='110617'!P77+'110617'!P78+'110717'!P77+'110717'!P78+'110817'!P77+'110817'!P78+'110917'!P77+'110917'!P78+'111017'!P77+'111017'!P78 | O8: ='110617'!Q77+'110617'!Q78+'110717'!Q77+'110717'!Q78+'110817'!Q77+'110817'!Q78+'110917'!Q77+'110917'!Q78+'111017'!Q77+'111017'!Q78 | P8: ='110617'!R77+'110617'!R78+'110717'!R77+'110717'!R78+'110817'!R77+'110817'!R78+'110917'!R77+'110917'!R78+'111017'!R77+'111017'!R78 | Q8: ='111317'!P77+'111317'!P78+'111417'!P77+'111417'!P78+'111517'!P77+'111517'!P78+'111617'!P77+'111617'!P78+'111717'!P77+'111717'!P78 | R8: ='111317'!Q77+'111317'!Q78+'111417'!Q77+'111417'!Q78+'111517'!Q77+'111517'!Q78+'111617'!Q77+'111617'!Q78+'111717'!Q77+'111717'!Q78 | S8: ='111317'!R77+'111317'!R78+'111417'!R77+'111417'!R78+'111517'!R77+'111517'!R78+'111617'!R77+'111617'!R78+'111717'!R77+'111717'!R78
A9: SPECIAL EFFECTS | B9: ='101317 PRESHOOT'!P85+'101317 PRESHOOT'!P86 | C9: ='101317 PRESHOOT'!Q85+'101317 PRESHOOT'!Q86 | D9: ='101317 PRESHOOT'!R85+'101317 PRESHOOT'!R86 | E9: ='101617'!P85+'101617'!P86+'101717'!P85+'101717'!P86+'101817'!P85+'101817'!P86+'101917'!P85+'101917'!P86+'102017'!P85+'102017'!P86 | F9: ='101617'!Q85+'101617'!Q86+'101717'!Q85+'101717'!Q86+'101817'!Q85+'101817'!Q86+'101917'!Q85+'101917'!Q86+'102017'!Q85+'102017'!Q86 | G9: ='101617'!R85+'101617'!R86+'101717'!R85+'101717'!R86+'101817'!R85+'101817'!R86+'101917'!R85+'101917'!R86+'102017'!R85+'102017'!R86 | H9: ='102317'!P85+'102317'!P86+'102417'!P85+'102417'!P86+'102517'!P85+'102517'!P86+'102617'!P85+'102617'!P86+'102717'!P85+'102717'!P86 | I9: ='102317'!Q85+'102317'!Q86+'102417'!Q85+'102417'!Q86+'102517'!Q85+'102517'!Q86+'102617'!Q85+'102617'!Q86+'102717'!Q85+'102717'!Q86 | J9: ='102317'!R85+'102317'!R86+'102417'!R85+'102417'!R86+'102517'!R85+'102517'!R86+'102617'!R85+'102617'!R86+'102717'!R85+'102717'!R86 | K9: ='103017'!P85+'103017'!P86+'103117'!P85+'103117'!P86+'110117'!P85+'110117'!P86+'110217'!P85+'110217'!P86+'110317'!P85+'110317'!P86 | L9: ='103017'!Q85+'103017'!Q86+'103117'!Q85+'103117'!Q86+'110117'!Q85+'110117'!Q86+'110217'!Q85+'110217'!Q86+'110317'!Q85+'110317'!Q86 | M9: ='103017'!R85+'103017'!R86+'103117'!R85+'103117'!R86+'110117'!R85+'110117'!R86+'110217'!R85+'110217'!R86+'110317'!R85+'110317'!R86 | N9: ='110617'!P85+'110617'!P86+'110717'!P85+'110717'!P86+'110817'!P85+'110817'!P86+'110917'!P85+'110917'!P86+'111017'!P85+'111017'!P86 | O9: ='110617'!Q85+'110617'!Q86+'110717'!Q85+'110717'!Q86+'110817'!Q85+'110817'!Q86+'110917'!Q85+'110917'!Q86+'111017'!Q85+'111017'!Q86 | P9: ='110617'!R85+'110617'!R86+'110717'!R85+'110717'!R86+'110817'!R85+'110817'!R86+'110917'!R85+'110917'!R86+'111017'!R85+'111017'!R86 | Q9: ='111317'!P85+'111317'!P86+'111417'!P85+'111417'!P86+'111517'!P85+'111517'!P86+'111617'!P85+'111617'!P86+'111717'!P85+'111717'!P86 | R9: ='111317'!Q85+'111317'!Q86+'111417'!Q85+'111417'!Q86+'111517'!Q85+'111517'!Q86+'111617'!Q85+'111617'!Q86+'111717'!Q85+'111717'!Q86 | S9: ='111317'!R85+'111317'!R86+'111417'!R85+'111417'!R86+'111517'!R85+'111517'!R86+'111617'!R85+'111617'!R86+'111717'!R85+'111717'!R86
A10: SET DRESSING | B10: ='101317 PRESHOOT'!P96+'101317 PRESHOOT'!P97 | C10: ='101317 PRESHOOT'!Q96+'101317 PRESHOOT'!Q97 | D10: ='101317 PRESHOOT'!R96+'101317 PRESHOOT'!R97 | E10: ='101617'!P96+'101617'!P97+'101717'!P96+'101717'!P97+'101817'!P96+'101817'!P97+'101917'!P96+'101917'!P97+'102017'!P96+'102017'!P97 | F10: ='101617'!Q96+'101617'!Q97+'101717'!Q96+'101717'!Q97+'101817'!Q96+'101817'!Q97+'101917'!Q96+'101917'!Q97+'102017'!Q96+'102017'!Q97 | G10: ='101617'!R96+'101617'!R97+'101717'!R96+'101717'!R97+'101817'!R96+'101817'!R97+'101917'!R96+'101917'!R97+'102017'!R96+'102017'!R97 | H10: ='102317'!P96+'102317'!P97+'102417'!P96+'102417'!P97+'102517'!P96+'102517'!P97+'102617'!P96+'102617'!P97+'102717'!P96+'102717'!P97 | I10: ='102317'!Q96+'102317'!Q97+'102417'!Q96+'102417'!Q97+'102517'!Q96+'102517'!Q97+'102617'!Q96+'102617'!Q97+'102717'!Q96+'102717'!Q97 | J10: ='102317'!R96+'102317'!R97+'102417'!R96+'102417'!R97+'102517'!R96+'102517'!R97+'102617'!R96+'102617'!R97+'102717'!R96+'102717'!R97 | K10: ='103017'!P96+'103017'!P97+'103117'!P96+'103117'!P97+'110117'!P96+'110117'!P97+'110217'!P96+'110217'!P97+'110317'!P96+'110317'!P97 | L10: ='103017'!Q96+'103017'!Q97+'103117'!Q96+'103117'!Q97+'110117'!Q96+'110117'!Q97+'110217'!Q96+'110217'!Q97+'110317'!Q96+'110317'!Q97 | M10: ='103017'!R96+'103017'!R97+'103117'!R96+'103117'!R97+'110117'!R96+'110117'!R97+'110217'!R96+'110217'!R97+'110317'!R96+'110317'!R97 | N10: ='110617'!P96+'110617'!P97+'110717'!P96+'110717'!P97+'110817'!P96+'110817'!P97+'110917'!P96+'110917'!P97+'111017'!P96+'111017'!P97 | O10: ='110617'!Q96+'110617'!Q97+'110717'!Q96+'110717'!Q97+'110817'!Q96+'110817'!Q97+'110917'!Q96+'110917'!Q97+'111017'!Q96+'111017'!Q97 | P10: ='110617'!R96+'110617'!R97+'110717'!R96+'110717'!R97+'110817'!R96+'110817'!R97+'110917'!R96+'110917'!R97+'111017'!R96+'111017'!R97 | Q10: ='111317'!P96+'111317'!P97+'111417'!P96+'111417'!P97+'111517'!P96+'111517'!P97+'111617'!P96+'111617'!P97+'111717'!P96+'111717'!P97 | R10: ='111317'!Q96+'111317'!Q97+'111417'!Q96+'111417'!Q97+'111517'!Q96+'111517'!Q97+'111617'!Q96+'111617'!Q97+'111717'!Q96+'111717'!Q97 | S10: ='111317'!R96+'111317'!R97+'111417'!R96+'111417'!R97+'111517'!R96+'111517'!R97+'111617'!R96+'111617'!R97+'111717'!R96+'111717'!R97
A11: PROPERTY | B11: ='101317 PRESHOOT'!P102+'101317 PRESHOOT'!P103 | C11: ='101317 PRESHOOT'!Q102+'101317 PRESHOOT'!Q103 | D11: ='101317 PRESHOOT'!R102+'101317 PRESHOOT'!R103 | E11: ='101617'!P102+'101617'!P103+'101717'!P102+'101717'!P103+'101817'!P102+'101817'!P103+'101917'!P102+'101917'!P103+'102017'!P102+'102017'!P103 | F11: ='101617'!Q102+'101617'!Q103+'101717'!Q102+'101717'!Q103+'101817'!Q102+'101817'!Q103+'101917'!Q102+'101917'!Q103+'102017'!Q102+'102017'!Q103 | G11: ='101617'!R102+'101617'!R103+'101717'!R102+'101717'!R103+'101817'!R102+'101817'!R103+'101917'!R102+'101917'!R103+'102017'!R102+'102017'!R103 | H11: ='102317'!P102+'102317'!P103+'102417'!P102+'102417'!P103+'102517'!P102+'102517'!P103+'102617'!P102+'102617'!P103+'102717'!P102+'102717'!P103 | I11: ='102317'!Q102+'102317'!Q103+'102417'!Q102+'102417'!Q103+'102517'!Q102+'102517'!Q103+'102617'!Q102+'102617'!Q103+'102717'!Q102+'102717'!Q103 | J11: ='102317'!R102+'102317'!R103+'102417'!R102+'102417'!R103+'102517'!R102+'102517'!R103+'102617'!R102+'102617'!R103+'102717'!R102+'102717'!R103 | K11: ='103017'!P102+'103017'!P103+'103117'!P102+'103117'!P103+'110117'!P102+'110117'!P103+'110217'!P102+'110217'!P103+'110317'!P102+'110317'!P103 | L11: ='103017'!Q102+'103017'!Q103+'103117'!Q102+'103117'!Q103+'110117'!Q102+'110117'!Q103+'110217'!Q102+'110217'!Q103+'110317'!Q102+'110317'!Q103 | M11: ='103017'!R102+'103017'!R103+'103117'!R102+'103117'!R103+'110117'!R102+'110117'!R103+'110217'!R102+'110217'!R103+'110317'!R102+'110317'!R103 | N11: ='110617'!P102+'110617'!P103+'110717'!P102+'110717'!P103+'110817'!P102+'110817'!P103+'110917'!P102+'110917'!P103+'111017'!P102+'111017'!P103 | O11: ='110617'!Q102+'110617'!Q103+'110717'!Q102+'110717'!Q103+'110817'!Q102+'110817'!Q103+'110917'!Q102+'110917'!Q103+'111017'!Q102+'111017'!Q103 | P11: ='110617'!R102+'110617'!R103+'110717'!R102+'110717'!R103+'110817'!R102+'110817'!R103+'110917'!R102+'110917'!R103+'111017'!R102+'111017'!R103 | Q11: ='111317'!P102+'111317'!P103+'111417'!P102+'111417'!P103+'111517'!P102+'111517'!P103+'111617'!P102+'111617'!P103+'111717'!P102+'111717'!P103 | R11: ='111317'!Q102+'111317'!Q103+'111417'!Q102+'111417'!Q103+'111517'!Q102+'111517'!Q103+'111617'!Q102+'111617'!Q103+'111717'!Q102+'111717'!Q103 | S11: ='111317'!R102+'111317'!R103+'111417'!R102+'111417'!R103+'111517'!R102+'111517'!R103+'111617'!R102+'111617'!R103+'111717'!R102+'111717'!R103
A12: WARDROBE | B12: ='101317 PRESHOOT'!P110+'101317 PRESHOOT'!P111 | C12: ='101317 PRESHOOT'!Q110+'101317 PRESHOOT'!Q111 | D12: ='101317 PRESHOOT'!R110+'101317 PRESHOOT'!R111 | E12: ='101617'!P110+'101617'!P111+'101717'!P110+'101717'!P111+'101817'!P110+'101817'!P111+'101917'!P110+'101917'!P111+'102017'!P110+'102017'!P111 | F12: ='101617'!Q110+'101617'!Q111+'101717'!Q110+'101717'!Q111+'101817'!Q110+'101817'!Q111+'101917'!Q110+'101917'!Q111+'102017'!Q110+'102017'!Q111 | G12: ='101617'!R110+'101617'!R111+'101717'!R110+'101717'!R111+'101817'!R110+'101817'!R111+'101917'!R110+'101917'!R111+'102017'!R110+'102017'!R111 | H12: ='102317'!P110+'102317'!P111+'102417'!P110+'102417'!P111+'102517'!P110+'102517'!P111+'102617'!P110+'102617'!P111+'102717'!P110+'102717'!P111 | I12: ='102317'!Q110+'102317'!Q111+'102417'!Q110+'102417'!Q111+'102517'!Q110+'102517'!Q111+'102617'!Q110+'102617'!Q111+'102717'!Q110+'102717'!Q111 | J12: ='102317'!R110+'102317'!R111+'102417'!R110+'102417'!R111+'102517'!R110+'102517'!R111+'102617'!R110+'102617'!R111+'102717'!R110+'102717'!R111 | K12: ='103017'!P110+'103017'!P111+'103117'!P110+'103117'!P111+'110117'!P110+'110117'!P111+'110217'!P110+'110217'!P111+'110317'!P110+'110317'!P111 | L12: ='103017'!Q110+'103017'!Q111+'103117'!Q110+'103117'!Q111+'110117'!Q110+'110117'!Q111+'110217'!Q110+'110217'!Q111+'110317'!Q110+'110317'!Q111 | M12: ='103017'!R110+'103017'!R111+'103117'!R110+'103117'!R111+'110117'!R110+'110117'!R111+'110217'!R110+'110217'!R111+'110317'!R110+'110317'!R111 | N12: ='110617'!P110+'110617'!P111+'110717'!P110+'110717'!P111+'110817'!P110+'110817'!P111+'110917'!P110+'110917'!P111+'111017'!P110+'111017'!P111 | O12: ='110617'!Q110+'110617'!Q111+'110717'!Q110+'110717'!Q111+'110817'!Q110+'110817'!Q111+'110917'!Q110+'110917'!Q111+'111017'!Q110+'111017'!Q111 | P12: ='110617'!R110+'110617'!R111+'110717'!R110+'110717'!R111+'110817'!R110+'110817'!R111+'110917'!R110+'110917'!R111+'111017'!R110+'111017'!R111 | Q12: ='111317'!P110+'111317'!P111+'111417'!P110+'111417'!P111+'111517'!P110+'111517'!P111+'111617'!P110+'111617'!P111+'111717'!P110+'111717'!P111 | R12: ='111317'!Q110+'111317'!Q111+'111417'!Q110+'111417'!Q111+'111517'!Q110+'111517'!Q111+'111617'!Q110+'111617'!Q111+'111717'!Q110+'111717'!Q111 | S12: ='111317'!R110+'111317'!R111+'111417'!R110+'111417'!R111+'111517'!R110+'111517'!R111+'111617'!R110+'111617'!R111+'111717'!R110+'111717'!R111
A13: MAKE-UP&HAIR | B13: ='101317 PRESHOOT'!P122+'101317 PRESHOOT'!P123 | C13: ='101317 PRESHOOT'!Q122+'101317 PRESHOOT'!Q123 | D13: ='101317 PRESHOOT'!R122+'101317 PRESHOOT'!R123 | E13: ='101617'!P122+'101617'!P123+'101717'!P122+'101717'!P123+'101817'!P122+'101817'!P123+'101917'!P122+'101917'!P123+'102017'!P122+'102017'!P123 | F13: ='101617'!Q122+'101617'!Q123+'101717'!Q122+'101717'!Q123+'101817'!Q122+'101817'!Q123+'101917'!Q122+'101917'!Q123+'102017'!Q122+'102017'!Q123 | G13: ='101617'!R122+'101617'!R123+'101717'!R122+'101717'!R123+'101817'!R122+'101817'!R123+'101917'!R122+'101917'!R123+'102017'!R122+'102017'!R123 | H13: ='102317'!P122+'102317'!P123+'102417'!P122+'102417'!P123+'102517'!P122+'102517'!P123+'102617'!P122+'102617'!P123+'102717'!P122+'102717'!P123 | I13: ='102317'!Q122+'102317'!Q123+'102417'!Q122+'102417'!Q123+'102517'!Q122+'102517'!Q123+'102617'!Q122+'102617'!Q123+'102717'!Q122+'102717'!Q123 | J13: ='102317'!R122+'102317'!R123+'102417'!R122+'102417'!R123+'102517'!R122+'102517'!R123+'102617'!R122+'102617'!R123+'102717'!R122+'102717'!R123 | K13: ='103017'!P122+'103017'!P123+'103117'!P122+'103117'!P123+'110117'!P122+'110117'!P123+'110217'!P122+'110217'!P123+'110317'!P122+'110317'!P123 | L13: ='103017'!Q122+'103017'!Q123+'103117'!Q122+'103117'!Q123+'110117'!Q122+'110117'!Q123+'110217'!Q122+'110217'!Q123+'110317'!Q122+'110317'!Q123 | M13: ='103017'!R122+'103017'!R123+'103117'!R122+'103117'!R123+'110117'!R122+'110117'!R123+'110217'!R122+'110217'!R123+'110317'!R122+'110317'!R123 | N13: ='110617'!P122+'110617'!P123+'110717'!P122+'110717'!P123+'110817'!P122+'110817'!P123+'110917'!P122+'110917'!P123+'111017'!P122+'111017'!P123 | O13: ='110617'!Q122+'110617'!Q123+'110717'!Q122+'110717'!Q123+'110817'!Q122+'110817'!Q123+'110917'!Q122+'110917'!Q123+'111017'!Q122+'111017'!Q123 | P13: ='110617'!R122+'110617'!R123+'110717'!R122+'110717'!R123+'110817'!R122+'110817'!R123+'110917'!R122+'110917'!R123+'111017'!R122+'111017'!R123 | Q13: ='111317'!P122+'111317'!P123+'111417'!P122+'111417'!P123+'111517'!P122+'111517'!P123+'111617'!P122+'111617'!P123+'111717'!P122+'111717'!P123 | R13: ='111317'!Q122+'111317'!Q123+'111417'!Q122+'111417'!Q123+'111517'!Q122+'111517'!Q123+'111617'!Q122+'111617'!Q123+'111717'!Q122+'111717'!Q123 | S13: ='111317'!R122+'111317'!R123+'111417'!R122+'111417'!R123+'111517'!R122+'111517'!R123+'111617'!R122+'111617'!R123+'111717'!R122+'111717'!R123
A14: SET LIGHTING | B14: ='101317 PRESHOOT'!P133+'101317 PRESHOOT'!P134 | C14: ='101317 PRESHOOT'!Q133+'101317 PRESHOOT'!Q134 | D14: ='101317 PRESHOOT'!R133+'101317 PRESHOOT'!R134 | E14: ='101617'!P133+'101617'!P134+'101717'!P133+'101717'!P134+'101817'!P133+'101817'!P134+'101917'!P133+'101917'!P134+'102017'!P133+'102017'!P134 | F14: ='101617'!Q133+'101617'!Q134+'101717'!Q133+'101717'!Q134+'101817'!Q133+'101817'!Q134+'101917'!Q133+'101917'!Q134+'102017'!Q133+'102017'!Q134 | G14: ='101617'!R133+'101617'!R134+'101717'!R133+'101717'!R134+'101817'!R133+'101817'!R134+'101917'!R133+'101917'!R134+'102017'!R133+'102017'!R134 | H14: ='102317'!P133+'102317'!P134+'102417'!P133+'102417'!P134+'102517'!P133+'102517'!P134+'102617'!P133+'102617'!P134+'102717'!P133+'102717'!P134 | I14: ='102317'!Q133+'102317'!Q134+'102417'!Q133+'102417'!Q134+'102517'!Q133+'102517'!Q134+'102617'!Q133+'102617'!Q134+'102717'!Q133+'102717'!Q134 | J14: ='102317'!R133+'102317'!R134+'102417'!R133+'102417'!R134+'102517'!R133+'102517'!R134+'102617'!R133+'102617'!R134+'102717'!R133+'102717'!R134 | K14: ='103017'!P133+'103017'!P134+'103117'!P133+'103117'!P134+'110117'!P133+'110117'!P134+'110217'!P133+'110217'!P134+'110317'!P133+'110317'!P134 | L14: ='103017'!Q133+'103017'!Q134+'103117'!Q133+'103117'!Q134+'110117'!Q133+'110117'!Q134+'110217'!Q133+'110217'!Q134+'110317'!Q133+'110317'!Q134 | M14: ='103017'!R133+'103017'!R134+'103117'!R133+'103117'!R134+'110117'!R133+'110117'!R134+'110217'!R133+'110217'!R134+'110317'!R133+'110317'!R134 | N14: ='110617'!P133+'110617'!P134+'110717'!P133+'110717'!P134+'110817'!P133+'110817'!P134+'110917'!P133+'110917'!P134+'111017'!P133+'111017'!P134 | O14: ='110617'!Q133+'110617'!Q134+'110717'!Q133+'110717'!Q134+'110817'!Q133+'110817'!Q134+'110917'!Q133+'110917'!Q134+'111017'!Q133+'111017'!Q134 | P14: ='110617'!R133+'110617'!R134+'110717'!R133+'110717'!R134+'110817'!R133+'110817'!R134+'110917'!R133+'110917'!R134+'111017'!R133+'111017'!R134 | Q14: ='111317'!P133+'111317'!P134+'111417'!P133+'111417'!P134+'111517'!P133+'111517'!P134+'111617'!P133+'111617'!P134+'111717'!P133+'111717'!P134 | R14: ='111317'!Q133+'111317'!Q134+'111417'!Q133+'111417'!Q134+'111517'!Q133+'111517'!Q134+'111617'!Q133+'111617'!Q134+'111717'!Q133+'111717'!Q134 | S14: ='111317'!R133+'111317'!R134+'111417'!R133+'111417'!R134+'111517'!R133+'111517'!R134+'111617'!R133+'111617'!R134+'111717'!R133+'111717'!R134
A15: CAMERA | B15: ='101317 PRESHOOT'!P146+'101317 PRESHOOT'!P147 | C15: ='101317 PRESHOOT'!Q146+'101317 PRESHOOT'!Q147 | D15: ='101317 PRESHOOT'!R146+'101317 PRESHOOT'!R147 | E15: ='101617'!P146+'101617'!P147+'101717'!P146+'101717'!P147+'101817'!P146+'101817'!P147+'101917'!P146+'101917'!P147+'102017'!P146+'102017'!P147 | F15: ='101617'!Q146+'101617'!Q147+'101717'!Q146+'101717'!Q147+'101817'!Q146+'101817'!Q147+'101917'!Q146+'101917'!Q147+'102017'!Q146+'102017'!Q147 | G15: ='101617'!R146+'101617'!R147+'101717'!R146+'101717'!R147+'101817'!R146+'101817'!R147+'101917'!R146+'101917'!R147+'102017'!R146+'102017'!R147 | H15: ='102317'!P146+'102317'!P147+'102417'!P146+'102417'!P147+'102517'!P146+'102517'!P147+'102617'!P146+'102617'!P147+'102717'!P146+'102717'!P147 | I15: ='102317'!Q146+'102317'!Q147+'102417'!Q146+'102417'!Q147+'102517'!Q146+'102517'!Q147+'102617'!Q146+'102617'!Q147+'102717'!Q146+'102717'!Q147 | J15: ='102317'!R146+'102317'!R147+'102417'!R146+'102417'!R147+'102517'!R146+'102517'!R147+'102617'!R146+'102617'!R147+'102717'!R146+'102717'!R147 | K15: ='103017'!P146+'103017'!P147+'103117'!P146+'103117'!P147+'110117'!P146+'110117'!P147+'110217'!P146+'110217'!P147+'110317'!P146+'110317'!P147 | L15: ='103017'!Q146+'103017'!Q147+'103117'!Q146+'103117'!Q147+'110117'!Q146+'110117'!Q147+'110217'!Q146+'110217'!Q147+'110317'!Q146+'110317'!Q147 | M15: ='103017'!R146+'103017'!R147+'103117'!R146+'103117'!R147+'110117'!R146+'110117'!R147+'110217'!R146+'110217'!R147+'110317'!R146+'110317'!R147 | N15: ='110617'!P146+'110617'!P147+'110717'!P146+'110717'!P147+'110817'!P146+'110817'!P147+'110917'!P146+'110917'!P147+'111017'!P146+'111017'!P147 | O15: ='110617'!Q146+'110617'!Q147+'110717'!Q146+'110717'!Q147+'110817'!Q146+'110817'!Q147+'110917'!Q146+'110917'!Q147+'111017'!Q146+'111017'!Q147 | P15: ='110617'!R146+'110617'!R147+'110717'!R146+'110717'!R147+'110817'!R146+'110817'!R147+'110917'!R146+'110917'!R147+'111017'!R146+'111017'!R147 | Q15: ='111317'!P146+'111317'!P147+'111417'!P146+'111417'!P147+'111517'!P146+'111517'!P147+'111617'!P146+'111617'!P147+'111717'!P146+'111717'!P147 | R15: ='111317'!Q146+'111317'!Q147+'111417'!Q146+'111417'!Q147+'111517'!Q146+'111517'!Q147+'111617'!Q146+'111617'!Q147+'111717'!Q146+'111717'!Q147 | S15: ='111317'!R146+'111317'!R147+'111417'!R146+'111417'!R147+'111517'!R146+'111517'!R147+'111617'!R146+'111617'!R147+'111717'!R146+'111717'!R147
A16: PRODUCTION SOUND | B16: ='101317 PRESHOOT'!P154+'101317 PRESHOOT'!P155 | C16: ='101317 PRESHOOT'!Q154+'101317 PRESHOOT'!Q155 | D16: ='101317 PRESHOOT'!R154+'101317 PRESHOOT'!R155 | E16: ='101617'!P154+'101617'!P155+'101717'!P154+'101717'!P155+'101817'!P154+'101817'!P155+'101917'!P154+'101917'!P155+'102017'!P154+'102017'!P155 | F16: ='101617'!Q154+'101617'!Q155+'101717'!Q154+'101717'!Q155+'101817'!Q154+'101817'!Q155+'101917'!Q154+'101917'!Q155+'102017'!Q154+'102017'!Q155 | G16: ='101617'!R154+'101617'!R155+'101717'!R154+'101717'!R155+'101817'!R154+'101817'!R155+'101917'!R154+'101917'!R155+'102017'!R154+'102017'!R155 | H16: ='102317'!P154+'102317'!P155+'102417'!P154+'102417'!P155+'102517'!P154+'102517'!P155+'102617'!P154+'102617'!P155+'102717'!P154+'102717'!P155 | I16: ='102317'!Q154+'102317'!Q155+'102417'!Q154+'102417'!Q155+'102517'!Q154+'102517'!Q155+'102617'!Q154+'102617'!Q155+'102717'!Q154+'102717'!Q155 | J16: ='102317'!R154+'102317'!R155+'102417'!R154+'102417'!R155+'102517'!R154+'102517'!R155+'102617'!R154+'102617'!R155+'102717'!R154+'102717'!R155 | K16: ='103017'!P154+'103017'!P155+'103117'!P154+'103117'!P155+'110117'!P154+'110117'!P155+'110217'!P154+'110217'!P155+'110317'!P154+'110317'!P155 | L16: ='103017'!Q154+'103017'!Q155+'103117'!Q154+'103117'!Q155+'110117'!Q154+'110117'!Q155+'110217'!Q154+'110217'!Q155+'110317'!Q154+'110317'!Q155 | M16: ='103017'!R154+'103017'!R155+'103117'!R154+'103117'!R155+'110117'!R154+'110117'!R155+'110217'!R154+'110217'!R155+'110317'!R154+'110317'!R155 | N16: ='110617'!P154+'110617'!P155+'110717'!P154+'110717'!P155+'110817'!P154+'110817'!P155+'110917'!P154+'110917'!P155+'111017'!P154+'111017'!P155 | O16: ='110617'!Q154+'110617'!Q155+'110717'!Q154+'110717'!Q155+'110817'!Q154+'110817'!Q155+'110917'!Q154+'110917'!Q155+'111017'!Q154+'111017'!Q155 | P16: ='110617'!R154+'110617'!R155+'110717'!R154+'110717'!R155+'110817'!R154+'110817'!R155+'110917'!R154+'110917'!R155+'111017'!R154+'111017'!R155 | Q16: ='111317'!P154+'111317'!P155+'111417'!P154+'111417'!P155+'111517'!P154+'111517'!P155+'111617'!P154+'111617'!P155+'111717'!P154+'111717'!P155 | R16: ='111317'!Q154+'111317'!Q155+'111417'!Q154+'111417'!Q155+'111517'!Q154+'111517'!Q155+'111617'!Q154+'111617'!Q155+'111717'!Q154+'111717'!Q155 | S16: ='111317'!R154+'111317'!R155+'111417'!R154+'111417'!R155+'111517'!R154+'111517'!R155+'111617'!R154+'111617'!R155+'111717'!R154+'111717'!R155
A17: TRANSPORTATION | B17: ='101317 PRESHOOT'!P172+'101317 PRESHOOT'!P173 | C17: ='101317 PRESHOOT'!Q172+'101317 PRESHOOT'!Q173 | D17: ='101317 PRESHOOT'!R172+'101317 PRESHOOT'!R173 | E17: ='101617'!P172+'101617'!P173+'101717'!P172+'101717'!P173+'101817'!P172+'101817'!P173+'101917'!P172+'101917'!P173+'102017'!P172+'102017'!P173 | F17: ='101617'!Q172+'101617'!Q173+'101717'!Q172+'101717'!Q173+'101817'!Q172+'101817'!Q173+'101917'!Q172+'101917'!Q173+'102017'!Q172+'102017'!Q173 | G17: ='101617'!R172+'101617'!R173+'101717'!R172+'101717'!R173+'101817'!R172+'101817'!R173+'101917'!R172+'101917'!R173+'102017'!R172+'102017'!R173 | H17: ='102317'!P172+'102317'!P173+'102417'!P172+'102417'!P173+'102517'!P172+'102517'!P173+'102617'!P172+'102617'!P173+'102717'!P172+'102717'!P173 | I17: ='102317'!Q172+'102317'!Q173+'102417'!Q172+'102417'!Q173+'102517'!Q172+'102517'!Q173+'102617'!Q172+'102617'!Q173+'102717'!Q172+'102717'!Q173 | J17: ='102317'!R172+'102317'!R173+'102417'!R172+'102417'!R173+'102517'!R172+'102517'!R173+'102617'!R172+'102617'!R173+'102717'!R172+'102717'!R173 | K17: ='103017'!P172+'103017'!P173+'103117'!P172+'103117'!P173+'110117'!P172+'110117'!P173+'110217'!P172+'110217'!P173+'110317'!P172+'110317'!P173 | L17: ='103017'!Q172+'103017'!Q173+'103117'!Q172+'103117'!Q173+'110117'!Q172+'110117'!Q173+'110217'!Q172+'110217'!Q173+'110317'!Q172+'110317'!Q173 | M17: ='103017'!R172+'103017'!R173+'103117'!R172+'103117'!R173+'110117'!R172+'110117'!R173+'110217'!R172+'110217'!R173+'110317'!R172+'110317'!R173 | N17: ='110617'!P172+'110617'!P173+'110717'!P172+'110717'!P173+'110817'!P172+'110817'!P173+'110917'!P172+'110917'!P173+'111017'!P172+'111017'!P173 | O17: ='110617'!Q172+'110617'!Q173+'110717'!Q172+'110717'!Q173+'110817'!Q172+'110817'!Q173+'110917'!Q172+'110917'!Q173+'111017'!Q172+'111017'!Q173 | P17: ='110617'!R172+'110617'!R173+'110717'!R172+'110717'!R173+'110817'!R172+'110817'!R173+'110917'!R172+'110917'!R173+'111017'!R172+'111017'!R173 | Q17: ='111317'!P172+'111317'!P173+'111417'!P172+'111417'!P173+'111517'!P172+'111517'!P173+'111617'!P172+'111617'!P173+'111717'!P172+'111717'!P173 | R17: ='111317'!Q172+'111317'!Q173+'111417'!Q172+'111417'!Q173+'111517'!Q172+'111517'!Q173+'111617'!Q172+'111617'!Q173+'111717'!Q172+'111717'!Q173 | S17: ='111317'!R172+'111317'!R173+'111417'!R172+'111417'!R173+'111517'!R172+'111517'!R173+'111617'!R172+'111617'!R173+'111717'!R172+'111717'!R173
A18: LOCATIONS | B18: ='101317 PRESHOOT'!P180+'101317 PRESHOOT'!P181 | C18: ='101317 PRESHOOT'!Q180+'101317 PRESHOOT'!Q181 | D18: ='101317 PRESHOOT'!R180+'101317 PRESHOOT'!R181 | E18: ='101617'!P180+'101617'!P181+'101717'!P180+'101717'!P181+'101817'!P180+'101817'!P181+'101917'!P180+'101917'!P181+'102017'!P180+'102017'!P181 | F18: ='101617'!Q180+'101617'!Q181+'101717'!Q180+'101717'!Q181+'101817'!Q180+'101817'!Q181+'101917'!Q180+'101917'!Q181+'102017'!Q180+'102017'!Q181 | G18: ='101617'!R180+'101617'!R181+'101717'!R180+'101717'!R181+'101817'!R180+'101817'!R181+'101917'!R180+'101917'!R181+'102017'!R180+'102017'!R181 | H18: ='102317'!P180+'102317'!P181+'102417'!P180+'102417'!P181+'102517'!P180+'102517'!P181+'102617'!P180+'102617'!P181+'102717'!P180+'102717'!P181 | I18: ='102317'!Q180+'102317'!Q181+'102417'!Q180+'102417'!Q181+'102517'!Q180+'102517'!Q181+'102617'!Q180+'102617'!Q181+'102717'!Q180+'102717'!Q181 | J18: ='102317'!R180+'102317'!R181+'102417'!R180+'102417'!R181+'102517'!R180+'102517'!R181+'102617'!R180+'102617'!R181+'102717'!R180+'102717'!R181 | K18: ='103017'!P180+'103017'!P181+'103117'!P180+'103117'!P181+'110117'!P180+'110117'!P181+'110217'!P180+'110217'!P181+'110317'!P180+'110317'!P181 | L18: ='103017'!Q180+'103017'!Q181+'103117'!Q180+'103117'!Q181+'110117'!Q180+'110117'!Q181+'110217'!Q180+'110217'!Q181+'110317'!Q180+'110317'!Q181 | M18: ='103017'!R180+'103017'!R181+'103117'!R180+'103117'!R181+'110117'!R180+'110117'!R181+'110217'!R180+'110217'!R181+'110317'!R180+'110317'!R181 | N18: ='110617'!P180+'110617'!P181+'110717'!P180+'110717'!P181+'110817'!P180+'110817'!P181+'110917'!P180+'110917'!P181+'111017'!P180+'111017'!P181 | O18: ='110617'!Q180+'110617'!Q181+'110717'!Q180+'110717'!Q181+'110817'!Q180+'110817'!Q181+'110917'!Q180+'110917'!Q181+'111017'!Q180+'111017'!Q181 | P18: ='110617'!R180+'110617'!R181+'110717'!R180+'110717'!R181+'110817'!R180+'110817'!R181+'110917'!R180+'110917'!R181+'111017'!R180+'111017'!R181 | Q18: ='111317'!P180+'111317'!P181+'111417'!P180+'111417'!P181+'111517'!P180+'111517'!P181+'111617'!P180+'111617'!P181+'111717'!P180+'111717'!P181 | R18: ='111317'!Q180+'111317'!Q181+'111417'!Q180+'111417'!Q181+'111517'!Q180+'111517'!Q181+'111617'!Q180+'111617'!Q181+'111717'!Q180+'111717'!Q181 | S18: ='111317'!R180+'111317'!R181+'111417'!R180+'111417'!R181+'111517'!R180+'111517'!R181+'111617'!R180+'111617'!R181+'111717'!R180+'111717'!R181
A19: TOTAL | B19: =SUM(B5:B18) | C19: =SUM(C5:C18) | D19: =SUM(D5:D18) | E19: =SUM(E5:E18) | F19: =SUM(F5:F18) | G19: =SUM(G5:G18) | H19: =SUM(H5:H18) | I19: =SUM(I5:I18) | ... S19: =SUM(S5:S18)

Sheet 101317 PRESHOOT
A1: HOT COST | C1: Friday 13 Oct 2017 | F1: PRESHOOT
A2: enter CALL, LUNCH, WRAP as decimal hours (e.g. 7.5) — everything right of WRAP computes
A4: ACCT | B4: NAME | C4: POSITION | D4: UNION | E4: RATE | F4: CALL | G4: LUNCH | H4: LUNCH 2 | I4: WRAP | J4: HRS | K4: MP'S | L4: ST | M4: 1.5X | N4: 2X | O4: 3X | P4: TOTAL / DAY | Q4: BUDGET / DAY | R4: (OVER) / UNDER
B5: CAST
A6: 1401 | B6: Linda Cardellini | C6: "ANNA" | E6: 1211.8 | J6: =IF(AND(N(F6)>0,N(I6)>0),I6-F6-IF(N(G6)>0,0.5,0)-IF(N(H6)>0,0.5,0),0) | L6: =MIN(J6,8.0) | M6: =MAX(0,MIN(J6,12)-8.0) | N6: =MAX(0,J6-12) | P6: =E6*(L6+M6*1.5+N6*2+O6*3+N(K6)) | Q6: 1211.8 | R6: =Q6-P6
A7: 1402 | B7: Roman Christou | C7: "CHRIS"(Minor) | E7: 755.4 | J7: =IF(AND(N(F7)>0,N(I7)>0),I7-F7-IF(N(G7)>0,0.5,0)-IF(N(H7)>0,0.5,0),0) | L7: =MIN(J7,8.0) | M7: =MAX(0,MIN(J7,12)-8.0) | N7: =MAX(0,J7-12) | P7: =E7*(L7+M7*1.5+N7*2+O7*3+N(K7)) | Q7: 755.4 | R7: =Q7-P7
A8: 1402 | B8: Jaynee Lynee Kinchen | C8: "SAMANTHA"(Minor) | E8: 755.4 | J8: =IF(AND(N(F8)>0,N(I8)>0),I8-F8-IF(N(G8)>0,0.5,0)-IF(N(H8)>0,0.5,0),0) | L8: =MIN(J8,8.0) | M8: =MAX(0,MIN(J8,12)-8.0) | N8: =MAX(0,J8-12) | P8: =E8*(L8+M8*1.5+N8*2+O8*3+N(K8)) | Q8: 755.4 | R8: =Q8-P8
A9: 1403 | B9: Raymond Cruz | C9: "RAFAELOLVERA" | E9: 1211.8 | J9: =IF(AND(N(F9)>0,N(I9)>0),I9-F9-IF(N(G9)>0,0.5,0)-IF(N(H9)>0,0.5,0),0) | L9: =MIN(J9,8.0) | M9: =MAX(0,MIN(J9,12)-8.0) | N9: =MAX(0,J9-12) | P9: =E9*(L9+M9*1.5+N9*2+O9*3+N(K9)) | Q9: 1211.8 | R9: =Q9-P9
A10: 1403 | B10: Marisol Ramirez | C10: "LALLORONA" | E10: 1211.8 | J10: =IF(AND(N(F10)>0,N(I10)>0),I10-F10-IF(N(G10)>0,0.5,0)-IF(N(H10)>0,0.5,0),0) | L10: =MIN(J10,8.0) | M10: =MAX(0,MIN(J10,12)-8.0) | N10: =MAX(0,J10-12) | P10: =E10*(L10+M10*1.5+N10*2+O10*3+N(K10)) | Q10: 1211.8 | R10: =Q10-P10
A11: 1403 | B11: Patrica Velasquez | C11: "PATRICIA" | E11: 1972 | J11: =IF(AND(N(F11)>0,N(I11)>0),I11-F11-IF(N(G11)>0,0.5,0)-IF(N(H11)>0,0.5,0),0) | L11: =MIN(J11,8.0) | M11: =MAX(0,MIN(J11,12)-8.0) | N11: =MAX(0,J11-12) | P11: =E11*(L11+M11*1.5+N11*2+O11*3+N(K11)) | Q11: 1972 | R11: =Q11-P11
A12: 1404 | B12: Sean Patrick Thomas | C12: DETCOOPER | E12: 1211.8 | J12: =IF(AND(N(F12)>0,N(I12)>0),I12-F12-IF(N(G12)>0,0.5,0)-IF(N(H12)>0,0.5,0),0) | L12: =MIN(J12,8.0) | M12: =MAX(0,MIN(J12,12)-8.0) | N12: =MAX(0,J12-12) | P12: =E12*(L12+M12*1.5+N12*2+O12*3+N(K12)) | Q12: 1211.8 | R12: =Q12-P12
A13: 1404 | B13: Tony Amendola | C13: "FA THE RPEREZ" | E13: 1972 | J13: =IF(AND(N(F13)>0,N(I13)>0),I13-F13-IF(N(G13)>0,0.5,0)-IF(N(H13)>0,0.5,0),0) | L13: =MIN(J13,8.0) | M13: =MAX(0,MIN(J13,12)-8.0) | N13: =MAX(0,J13-12) | P13: =E13*(L13+M13*1.5+N13*2+O13*3+N(K13)) | Q13: 1972 | R13: =Q13-P13
A14: 1405 | B14: Kristy Keng(Drop/Pickup) | C14: "DONNA" | E14: 1972 | J14: =IF(AND(N(F14)>0,N(I14)>0),I14-F14-IF(N(G14)>0,0.5,0)-IF(N(H14)>0,0.5,0),0) | L14: =MIN(J14,8.0) | M14: =MAX(0,MIN(J14,12)-8.0) | N14: =MAX(0,J14-12) | P14: =E14*(L14+M14*1.5+N14*2+O14*3+N(K14)) | Q14: 1972 | R14: =Q14-P14
A15: 1405 | B15: Oliver Alexander | C15: "CARLOS"(Minor) | E15: 1249 | J15: =IF(AND(N(F15)>0,N(I15)>0),I15-F15-IF(N(G15)>0,0.5,0)-IF(N(H15)>0,0.5,0),0) | L15: =MIN(J15,8.0) | M15: =MAX(0,MIN(J15,12)-8.0) | N15: =MAX(0,J15-12) | P15: =E15*(L15+M15*1.5+N15*2+O15*3+N(K15)) | Q15: 1249 | R15: =Q15-P15
A16: 1405 | B16: Adam Lewandowski | C16: "TOMAS"(Minor) | E16: 1249 | J16: =IF(AND(N(F16)>0,N(I16)>0),I16-F16-IF(N(G16)>0,0.5,0)-IF(N(H16)>0,0.5,0),0) | L16: =MIN(J16,8.0) | M16: =MAX(0,MIN(J16,12)-8.0) | N16: =MAX(0,J16-12) | P16: =E16*(L16+M16*1.5+N16*2+O16*3+N(K16)) | Q16: 1249 | R16: =Q16-P16
A17: 1405 | B17: Paul Rodriquez Jr. | C17: "OFFICERCLARO" | E17: 1972 | J17: =IF(AND(N(F17)>0,N(I17)>0),I17-F17-IF(N(G17)>0,0.5,0)-IF(N(H17)>0,0.5,0),0) | L17: =MIN(J17,8.0) | M17: =MAX(0,MIN(J17,12)-8.0) | N17: =MAX(0,J17-12) | P17: =E17*(L17+M17*1.5+N17*2+O17*3+N(K17)) | Q17: 1972 | R17: =Q17-P17
... A21: 1406 | B21: Rob King | C21: STUNT COORDINATOR | E21: 1173 | J21: =IF(AND(N(F21)>0,N(I21)>0),I21-F21-IF(N(G21)>0,0.5,0)-IF(N(H21)>0,0.5,0),0) | L21: =MIN(J21,8.0) | M21: =MAX(0,MIN(J21,12)-8.0) | N21: =MAX(0,J21-12) | P21: =E21*(L21+M21*1.5+N21*2+O21*3+N(K21)) | Q21: 1173 | R21: =Q21-P21
A22: 1412 | C22: WELFAREWORKER | D22: Local884 | E22: 25.5 | J22: =IF(AND(N(F22)>0,N(I22)>0),I22-F22-IF(N(G22)>0,0.5,0)-IF(N(H22)>0,0.5,0),0) | L22: =MIN(J22,8.0) | M22: =MAX(0,MIN(J22,12)-8.0) | N22: =MAX(0,J22-12) | P22: =E22*(L22+M22*1.5+N22*2+O22*3+N(K22)) | Q22: 280.5 | R22: =Q22-P22
A23: 1412 | C23: ADDLWELFAREWORKER | D23: Local884 | E23: 25.5 | J23: =IF(AND(N(F23)>0,N(I23)>0),I23-F23-IF(N(G23)>0,0.5,0)-IF(N(H23)>0,0.5,0),0) | L23: =MIN(J23,8.0) | M23: =MAX(0,MIN(J23,12)-8.0) | N23: =MAX(0,J23-12) | P23: =E23*(L23+M23*1.5+N23*2+O23*3+N(K23)) | R23: =Q23-P23
A24: 1413 | B24: Rich Delia | C24: CASTING DIRECTOR | E24: 600 | J24: =IF(AND(N(F24)>0,N(I24)>0),I24-F24-IF(N(G24)>0,0.5,0)-IF(N(H24)>0,0.5,0),0) | L24: =MIN(J24,8.0) | M24: =MAX(0,MIN(J24,12)-8.0) | N24: =MAX(0,J24-12) | P24: =E24*(L24+M24*1.5+N24*2+O24*3+N(K24)) | R24: =Q24-P24
A25: 1414 | B25: Adam Richards | C25: CASTING ASSOCIATE | E25: 200 | J25: =IF(AND(N(F25)>0,N(I25)>0),I25-F25-IF(N(G25)>0,0.5,0)-IF(N(H25)>0,0.5,0),0) | L25: =MIN(J25,8.0) | M25: =MAX(0,MIN(J25,12)-8.0) | N25: =MAX(0,J25-12) | P25: =E25*(L25+M25*1.5+N25*2+O25*3+N(K25)) | R25: =Q25-P25
A26: 1455 | C26: CAST 3-RMDRIVER | D26: Local399 | E26: 32.36 | J26: =IF(AND(N(F26)>0,N(I26)>0),I26-F26-IF(N(G26)>0,0.5,0)-IF(N(H26)>0,0.5,0),0) | L26: =MIN(J26,8.0) | M26: =MAX(0,MIN(J26,12)-8.0) | N26: =MAX(0,J26-12) | P26: =E26*(L26+M26*1.5+N26*2+O26*3+N(K26)) | Q26: 453.04 | R26: =Q26-P26
A27: 1455 | C27: CAST MINIV AND RIVER | D27: Local399 | E27: 32.36 | J27: =IF(AND(N(F27)>0,N(I27)>0),I27-F27-IF(N(G27)>0,0.5,0)-IF(N(H27)>0,0.5,0),0) | L27: =MIN(J27,8.0) | M27: =MAX(0,MIN(J27,12)-8.0) | N27: =MAX(0,J27-12) | P27: =E27*(L27+M27*1.5+N27*2+O27*3+N(K27)) | Q27: 453.04 | R27: =Q27-P27
C28: CAST LABOR | P28: =SUM(P6:P27) | Q28: =SUM(Q6:Q27) | R28: =SUM(R6:R27)
C29: CAST FRINGE | E29: 0.3842 | P29: =P28*0.3842 | Q29: =Q28*0.3842 | R29: =R28*0.3842
B31: PRODUCTION STAFF
A32: 2001 | B32: Carrie Morrow | C32: UPM | D32: DGA | E32: 1063.6 | J32: =IF(AND(N(F32)>0,N(I32)>0),I32-F32-IF(N(G32)>0,0.5,0)-IF(N(H32)>0,0.5,0),0) | L32: =MIN(J32,8.0) | M32: =MAX(0,MIN(J32,12)-8.0) | N32: =MAX(0,J32-12) | P32: =E32*(L32+M32*1.5+N32*2+O32*3+N(K32)) | Q32: 1063.6 | R32: =Q32-P32
A33: 2002 | B33: James Moran | C33: 1STASST DIRECTOR | D33: DGA | E33: 985.6 | J33: =IF(AND(N(F33)>0,N(I33)>0),I33-F33-IF(N(G33)>0,0.5,0)-IF(N(H33)>0,0.5,0),0) | L33: =MIN(J33,8.0) | M33: =MAX(0,MIN(J33,12)-8.0) | N33: =MAX(0,J33-12) | P33: =E33*(L33+M33*1.5+N33*2+O33*3+N(K33)) | Q33: 985.6 | R33: =Q33-P33
A34: 2003 | B34: Mark Newland | C34: KEY 2NDA. D. | D34: DGA | E34: 674.6 | J34: =IF(AND(N(F34)>0,N(I34)>0),I34-F34-IF(N(G34)>0,0.5,0)-IF(N(H34)>0,0.5,0),0) | L34: =MIN(J34,8.0) | M34: =MAX(0,MIN(J34,12)-8.0) | N34: =MAX(0,J34-12) | P34: =E34*(L34+M34*1.5+N34*2+O34*3+N(K34)) | Q34: 674.6 | R34: =Q34-P34
A35: 2003 | C35: 2ND 2NDA. D. | D35: DGA | E35: 526 | J35: =IF(AND(N(F35)>0,N(I35)>0),I35-F35-IF(N(G35)>0,0.5,0)-IF(N(H35)>0,0.5,0),0) | L35: =MIN(J35,8.0) | M35: =MAX(0,MIN(J35,12)-8.0) | N35: =MAX(0,J35-12) | P35: =E35*(L35+M35*1.5+N35*2+O35*3+N(K35)) | Q35: 526 | R35: =Q35-P35
A36: 2005 | B36: Renata Amador | C36: SCRIPT SUPERVISOR | D36: Local871 | E36: 25.5 | J36: =IF(AND(N(F36)>0,N(I36)>0),I36-F36-IF(N(G36)>0,0.5,0)-IF(N(H36)>0,0.5,0),0) | L36: =MIN(J36,10.0) | M36: =MAX(0,MIN(J36,12)-10.0) | N36: =MAX(0,J36-12) | P36: =E36*(L36+M36*1.5+N36*2+O36*3+N(K36)) | Q36: 280.5 | R36: =Q36-P36
A37: 2007 | B37: Stacey Brashear-Rodriquez | C37: LOCATION MANAGER | D37: Local399 | E37: 557.6 | J37: =IF(AND(N(F37)>0,N(I37)>0),I37-F37-IF(N(G37)>0,0.5,0)-IF(N(H37)>0,0.5,0),0) | L37: =MIN(J37,8.0) | M37: =MAX(0,MIN(J37,12)-8.0) | N37: =MAX(0,J37-12) | P37: =E37*(L37+M37*1.5+N37*2+O37*3+N(K37)) | Q37: 557.6 | R37: =Q37-P37
A38: 2008 | B38: Rich Heichel | C38: KEYASST LOCATION MGR#1 | D38: Local399 | E38: 334.2 | J38: =IF(AND(N(F38)>0,N(I38)>0),I38-F38-IF(N(G38)>0,0.5,0)-IF(N(H38)>0,0.5,0),0) | L38: =MIN(J38,8.0) | M38: =MAX(0,MIN(J38,12)-8.0) | N38: =MAX(0,J38-12) | P38: =E38*(L38+M38*1.5+N38*2+O38*3+N(K38)) | Q38: 334.2 | R38: =Q38-P38
A39: 2008 | B39: Jason Mc Cauley | C39: LOCATION ASST | D39: Local399 | E39: 229 | J39: =IF(AND(N(F39)>0,N(I39)>0),I39-F39-IF(N(G39)>0,0.5,0)-IF(N(H39)>0,0.5,0),0) | L39: =MIN(J39,8.0) | M39: =MAX(0,MIN(J39,12)-8.0) | N39: =MAX(0,J39-12) | P39: =E39*(L39+M39*1.5+N39*2+O39*3+N(K39)) | Q39: 229 | R39: =Q39-P39
A40: 2009 | B40: Ali Griffith | C40: PRODUCTION OFCCOORD | E40: 360 | J40: =IF(AND(N(F40)>0,N(I40)>0),I40-F40-IF(N(G40)>0,0.5,0)-IF(N(H40)>0,0.5,0),0) | L40: =MIN(J40,8.0) | M40: =MAX(0,MIN(J40,12)-8.0) | N40: =MAX(0,J40-12) | P40: =E40*(L40+M40*1.5+N40*2+O40*3+N(K40)) | Q40: 360 | R40: =Q40-P40
A41: 2010 | B41: Holly Dellocono | C41: APOC | D41: Local871 | E41: 20.57 | J41: =IF(AND(N(F41)>0,N(I41)>0),I41-F41-IF(N(G41)>0,0.5,0)-IF(N(H41)>0,0.5,0),0) | L41: =MIN(J41,10.0) | M41: =MAX(0,MIN(J41,12)-10.0) | N41: =MAX(0,J41-12) | P41: =E41*(L41+M41*1.5+N41*2+O41*3+N(K41)) | Q41: 287.98 | R41: =Q41-P41
A42: 2011 | B42: John Humber | C42: OFFICEPA#1 | E42: 22.5 | J42: =IF(AND(N(F42)>0,N(I42)>0),I42-F42-IF(N(G42)>0,0.5,0)-IF(N(H42)>0,0.5,0),0) | L42: =MIN(J42,8.0) | M42: =MAX(0,MIN(J42,12)-8.0) | N42: =MAX(0,J42-12) | P42: =E42*(L42+M42*1.5+N42*2+O42*3+N(K42)) | Q42: 247.5 | R42: =Q42-P42
A43: 2011 | B43: Sarah Semenas | C43: OFFICEPA#2 | E43: 22.5 | J43: =IF(AND(N(F43)>0,N(I43)>0),I43-F43-IF(N(G43)>0,0.5,0)-IF(N(H43)>0,0.5,0),0) | L43: =MIN(J43,8.0) | M43: =MAX(0,MIN(J43,12)-8.0) | N43: =MAX(0,J43-12) | P43: =E43*(L43+M43*1.5+N43*2+O43*3+N(K43)) | Q43: 247.5 | R43: =Q43-P43
A44: 2012 | B44: Paula Henry | C44: KEY SET PA | E44: 12 | J44: =IF(AND(N(F44)>0,N(I44)>0),I44-F44-IF(N(G44)>0,0.5,0)-IF(N(H44)>0,0.5,0),0) | L44: =MIN(J44,8.0) | M44: =MAX(0,MIN(J44,12)-8.0) | N44: =MAX(0,J44-12) | P44: =E44*(L44+M44*1.5+N44*2+O44*3+N(K44)) | Q44: 216 | R44: =Q44-P44
A45: 2012 | C45: SETPA#2 | E45: 12 | J45: =IF(AND(N(F45)>0,N(I45)>0),I45-F45-IF(N(G45)>0,0.5,0)-IF(N(H45)>0,0.5,0),0) | L45: =MIN(J45,8.0) | M45: =MAX(0,MIN(J45,12)-8.0) | N45: =MAX(0,J45-12) | P45: =E45*(L45+M45*1.5+N45*2+O45*3+N(K45)) | Q45: 216 | R45: =Q45-P45
...

Sheet 101617
A1: HOT COST | C1: Monday 16 Oct 2017 | F1: DAY #1
A2: enter CALL, LUNCH, WRAP as decimal hours (e.g. 7.5) — everything right of WRAP computes
A4: ACCT | B4: NAME | C4: POSITION | D4: UNION | E4: RATE | F4: CALL | G4: LUNCH | H4: LUNCH 2 | I4: WRAP | J4: HRS | K4: MP'S | L4: ST | M4: 1.5X | N4: 2X | O4: 3X | P4: TOTAL / DAY | Q4: BUDGET / DAY | R4: (OVER) / UNDER
B5: CAST
A6: 1401 | B6: Linda Cardellini | C6: "ANNA" | E6: 1211.8 | J6: =IF(AND(N(F6)>0,N(I6)>0),I6-F6-IF(N(G6)>0,0.5,0)-IF(N(H6)>0,0.5,0),0) | L6: =MIN(J6,8.0) | M6: =MAX(0,MIN(J6,12)-8.0) | N6: =MAX(0,J6-12) | P6: =E6*(L6+M6*1.5+N6*2+O6*3+N(K6)) | Q6: 1211.8 | R6: =Q6-P6
A7: 1402 | B7: Roman Christou | C7: "CHRIS"(Minor) | E7: 755.4 | J7: =IF(AND(N(F7)>0,N(I7)>0),I7-F7-IF(N(G7)>0,0.5,0)-IF(N(H7)>0,0.5,0),0) | L7: =MIN(J7,8.0) | M7: =MAX(0,MIN(J7,12)-8.0) | N7: =MAX(0,J7-12) | P7: =E7*(L7+M7*1.5+N7*2+O7*3+N(K7)) | Q7: 755.4 | R7: =Q7-P7
A8: 1402 | B8: Jaynee Lynee Kinchen | C8: "SAMANTHA"(Minor) | E8: 755.4 | J8: =IF(AND(N(F8)>0,N(I8)>0),I8-F8-IF(N(G8)>0,0.5,0)-IF(N(H8)>0,0.5,0),0) | L8: =MIN(J8,8.0) | M8: =MAX(0,MIN(J8,12)-8.0) | N8: =MAX(0,J8-12) | P8: =E8*(L8+M8*1.5+N8*2+O8*3+N(K8)) | Q8: 755.4 | R8: =Q8-P8
A9: 1403 | B9: Raymond Cruz | C9: "RAFAELOLVERA" | E9: 1211.8 | J9: =IF(AND(N(F9)>0,N(I9)>0),I9-F9-IF(N(G9)>0,0.5,0)-IF(N(H9)>0,0.5,0),0) | L9: =MIN(J9,8.0) | M9: =MAX(0,MIN(J9,12)-8.0) | N9: =MAX(0,J9-12) | P9: =E9*(L9+M9*1.5+N9*2+O9*3+N(K9)) | Q9: 1211.8 | R9: =Q9-P9
A10: 1403 | B10: Marisol Ramirez | C10: "LALLORONA" | E10: 1211.8 | J10: =IF(AND(N(F10)>0,N(I10)>0),I10-F10-IF(N(G10)>0,0.5,0)-IF(N(H10)>0,0.5,0),0) | L10: =MIN(J10,8.0) | M10: =MAX(0,MIN(J10,12)-8.0) | N10: =MAX(0,J10-12) | P10: =E10*(L10+M10*1.5+N10*2+O10*3+N(K10)) | Q10: 1211.8 | R10: =Q10-P10
A11: 1403 | B11: Patrica Velasquez | C11: "PATRICIA" | E11: 1972 | J11: =IF(AND(N(F11)>0,N(I11)>0),I11-F11-IF(N(G11)>0,0.5,0)-IF(N(H11)>0,0.5,0),0) | L11: =MIN(J11,8.0) | M11: =MAX(0,MIN(J11,12)-8.0) | N11: =MAX(0,J11-12) | P11: =E11*(L11+M11*1.5+N11*2+O11*3+N(K11)) | Q11: 1972 | R11: =Q11-P11
